[2024-01-21T09:24:33.213+0000] {taskinstance.py:1957} INFO - Dependencies all met for dep_context=non-requeueable deps ti=<TaskInstance: Python_dag.run_python manual__2024-01-21T09:24:32.248826+00:00 [queued]>
[2024-01-21T09:24:33.230+0000] {taskinstance.py:1957} INFO - Dependencies all met for dep_context=requeueable deps ti=<TaskInstance: Python_dag.run_python manual__2024-01-21T09:24:32.248826+00:00 [queued]>
[2024-01-21T09:24:33.232+0000] {taskinstance.py:2171} INFO - Starting attempt 1 of 6
[2024-01-21T09:24:33.271+0000] {taskinstance.py:2192} INFO - Executing <Task(PythonOperator): run_python> on 2024-01-21 09:24:32.248826+00:00
[2024-01-21T09:24:33.278+0000] {standard_task_runner.py:60} INFO - Started process 2794 to run task
[2024-01-21T09:24:33.282+0000] {standard_task_runner.py:87} INFO - Running: ['***', 'tasks', 'run', 'Python_dag', 'run_python', 'manual__2024-01-21T09:24:32.248826+00:00', '--job-id', '34', '--raw', '--subdir', 'DAGS_FOLDER/python_dag.py', '--cfg-path', '/tmp/tmp1trwgvue']
[2024-01-21T09:24:33.287+0000] {standard_task_runner.py:88} INFO - Job 34: Subtask run_python
[2024-01-21T09:24:33.360+0000] {task_command.py:423} INFO - Running <TaskInstance: Python_dag.run_python manual__2024-01-21T09:24:32.248826+00:00 [running]> on host 48444e3206b7
[2024-01-21T09:24:33.494+0000] {taskinstance.py:2481} INFO - Exporting env vars: AIRFLOW_CTX_DAG_OWNER='Rhon' AIRFLOW_CTX_DAG_ID='Python_dag' AIRFLOW_CTX_TASK_ID='run_python' AIRFLOW_CTX_EXECUTION_DATE='2024-01-21T09:24:32.248826+00:00' AIRFLOW_CTX_TRY_NUMBER='1' AIRFLOW_CTX_DAG_RUN_ID='manual__2024-01-21T09:24:32.248826+00:00'
[2024-01-21T09:24:33.498+0000] {taskinstance.py:2699} ERROR - Task failed with exception
Traceback (most recent call last):
  File "/home/airflow/.local/lib/python3.8/site-packages/airflow/models/taskinstance.py", line 433, in _execute_task
    result = execute_callable(context=context, **execute_callable_kwargs)
  File "/home/airflow/.local/lib/python3.8/site-packages/airflow/operators/python.py", line 199, in execute
    return_value = self.execute_callable()
  File "/home/airflow/.local/lib/python3.8/site-packages/airflow/operators/python.py", line 216, in execute_callable
    return self.python_callable(*self.op_args, **self.op_kwargs)
  File "/opt/airflow/dags/python_dag.py", line 6, in greet
    print(f'Good morning {name}, its {time_} already')
NameError: name 'name' is not defined
[2024-01-21T09:24:33.515+0000] {taskinstance.py:1138} INFO - Marking task as UP_FOR_RETRY. dag_id=Python_dag, task_id=run_python, execution_date=20240121T092432, start_date=20240121T092433, end_date=20240121T092433
[2024-01-21T09:24:33.538+0000] {standard_task_runner.py:107} ERROR - Failed to execute job 34 for task run_python (name 'name' is not defined; 2794)
[2024-01-21T09:24:33.579+0000] {local_task_job_runner.py:234} INFO - Task exited with return code 1
[2024-01-21T09:24:33.607+0000] {taskinstance.py:3281} INFO - 0 downstream tasks scheduled from follow-on schedule check
