[2024-01-21T09:26:03.435+0000] {taskinstance.py:1957} INFO - Dependencies all met for dep_context=non-requeueable deps ti=<TaskInstance: Python_dag.run_python manual__2024-01-21T09:24:01.598025+00:00 [queued]>
[2024-01-21T09:26:03.449+0000] {taskinstance.py:1957} INFO - Dependencies all met for dep_context=requeueable deps ti=<TaskInstance: Python_dag.run_python manual__2024-01-21T09:24:01.598025+00:00 [queued]>
[2024-01-21T09:26:03.450+0000] {taskinstance.py:2171} INFO - Starting attempt 2 of 6
[2024-01-21T09:26:03.471+0000] {taskinstance.py:2192} INFO - Executing <Task(PythonOperator): run_python> on 2024-01-21 09:24:01.598025+00:00
[2024-01-21T09:26:03.477+0000] {standard_task_runner.py:60} INFO - Started process 2844 to run task
[2024-01-21T09:26:03.481+0000] {standard_task_runner.py:87} INFO - Running: ['***', 'tasks', 'run', 'Python_dag', 'run_python', 'manual__2024-01-21T09:24:01.598025+00:00', '--job-id', '35', '--raw', '--subdir', 'DAGS_FOLDER/python_dag.py', '--cfg-path', '/tmp/tmp4fj_e9qv']
[2024-01-21T09:26:03.487+0000] {standard_task_runner.py:88} INFO - Job 35: Subtask run_python
[2024-01-21T09:26:03.560+0000] {task_command.py:423} INFO - Running <TaskInstance: Python_dag.run_python manual__2024-01-21T09:24:01.598025+00:00 [running]> on host 48444e3206b7
[2024-01-21T09:26:03.693+0000] {taskinstance.py:2481} INFO - Exporting env vars: AIRFLOW_CTX_DAG_OWNER='Rhon' AIRFLOW_CTX_DAG_ID='Python_dag' AIRFLOW_CTX_TASK_ID='run_python' AIRFLOW_CTX_EXECUTION_DATE='2024-01-21T09:24:01.598025+00:00' AIRFLOW_CTX_TRY_NUMBER='2' AIRFLOW_CTX_DAG_RUN_ID='manual__2024-01-21T09:24:01.598025+00:00'
[2024-01-21T09:26:03.695+0000] {taskinstance.py:2699} ERROR - Task failed with exception
Traceback (most recent call last):
  File "/home/airflow/.local/lib/python3.8/site-packages/airflow/models/taskinstance.py", line 433, in _execute_task
    result = execute_callable(context=context, **execute_callable_kwargs)
  File "/home/airflow/.local/lib/python3.8/site-packages/airflow/operators/python.py", line 199, in execute
    return_value = self.execute_callable()
  File "/home/airflow/.local/lib/python3.8/site-packages/airflow/operators/python.py", line 216, in execute_callable
    return self.python_callable(*self.op_args, **self.op_kwargs)
  File "/opt/airflow/dags/python_dag.py", line 6, in greet
    print(f'Good morning {name}, its {time_} already')
NameError: name 'name' is not defined
[2024-01-21T09:26:03.710+0000] {taskinstance.py:1138} INFO - Marking task as UP_FOR_RETRY. dag_id=Python_dag, task_id=run_python, execution_date=20240121T092401, start_date=20240121T092603, end_date=20240121T092603
[2024-01-21T09:26:03.727+0000] {standard_task_runner.py:107} ERROR - Failed to execute job 35 for task run_python (name 'name' is not defined; 2844)
[2024-01-21T09:26:03.735+0000] {local_task_job_runner.py:234} INFO - Task exited with return code 1
[2024-01-21T09:26:03.758+0000] {taskinstance.py:3281} INFO - 0 downstream tasks scheduled from follow-on schedule check
