[2024-01-21T09:24:07.716+0000] {taskinstance.py:1957} INFO - Dependencies all met for dep_context=non-requeueable deps ti=<TaskInstance: Python_dag.run_python manual__2024-01-21T09:24:06.759126+00:00 [queued]>
[2024-01-21T09:24:07.742+0000] {taskinstance.py:1957} INFO - Dependencies all met for dep_context=requeueable deps ti=<TaskInstance: Python_dag.run_python manual__2024-01-21T09:24:06.759126+00:00 [queued]>
[2024-01-21T09:24:07.745+0000] {taskinstance.py:2171} INFO - Starting attempt 1 of 6
[2024-01-21T09:24:07.779+0000] {taskinstance.py:2192} INFO - Executing <Task(PythonOperator): run_python> on 2024-01-21 09:24:06.759126+00:00
[2024-01-21T09:24:07.787+0000] {standard_task_runner.py:60} INFO - Started process 2781 to run task
[2024-01-21T09:24:07.795+0000] {standard_task_runner.py:87} INFO - Running: ['***', 'tasks', 'run', 'Python_dag', 'run_python', 'manual__2024-01-21T09:24:06.759126+00:00', '--job-id', '33', '--raw', '--subdir', 'DAGS_FOLDER/python_dag.py', '--cfg-path', '/tmp/tmpiderx7pf']
[2024-01-21T09:24:07.801+0000] {standard_task_runner.py:88} INFO - Job 33: Subtask run_python
[2024-01-21T09:24:07.882+0000] {task_command.py:423} INFO - Running <TaskInstance: Python_dag.run_python manual__2024-01-21T09:24:06.759126+00:00 [running]> on host 48444e3206b7
[2024-01-21T09:24:08.012+0000] {taskinstance.py:2481} INFO - Exporting env vars: AIRFLOW_CTX_DAG_OWNER='Rhon' AIRFLOW_CTX_DAG_ID='Python_dag' AIRFLOW_CTX_TASK_ID='run_python' AIRFLOW_CTX_EXECUTION_DATE='2024-01-21T09:24:06.759126+00:00' AIRFLOW_CTX_TRY_NUMBER='1' AIRFLOW_CTX_DAG_RUN_ID='manual__2024-01-21T09:24:06.759126+00:00'
[2024-01-21T09:24:08.014+0000] {taskinstance.py:2699} ERROR - Task failed with exception
Traceback (most recent call last):
  File "/home/airflow/.local/lib/python3.8/site-packages/airflow/models/taskinstance.py", line 433, in _execute_task
    result = execute_callable(context=context, **execute_callable_kwargs)
  File "/home/airflow/.local/lib/python3.8/site-packages/airflow/operators/python.py", line 199, in execute
    return_value = self.execute_callable()
  File "/home/airflow/.local/lib/python3.8/site-packages/airflow/operators/python.py", line 216, in execute_callable
    return self.python_callable(*self.op_args, **self.op_kwargs)
  File "/opt/airflow/dags/python_dag.py", line 6, in greet
    print(f'Good morning {name}, its {time_} already')
NameError: name 'name' is not defined
[2024-01-21T09:24:08.029+0000] {taskinstance.py:1138} INFO - Marking task as UP_FOR_RETRY. dag_id=Python_dag, task_id=run_python, execution_date=20240121T092406, start_date=20240121T092407, end_date=20240121T092408
[2024-01-21T09:24:08.048+0000] {standard_task_runner.py:107} ERROR - Failed to execute job 33 for task run_python (name 'name' is not defined; 2781)
[2024-01-21T09:24:08.089+0000] {local_task_job_runner.py:234} INFO - Task exited with return code 1
[2024-01-21T09:24:08.115+0000] {taskinstance.py:3281} INFO - 0 downstream tasks scheduled from follow-on schedule check
